<?xml version="1.0" ?>
<!-- =================================================================================== -->
<!-- |    This document was autogenerated by xacro from doozy.xacro                 | -->
<!-- |    EDITING THIS FILE BY HAND IS NOT RECOMMENDED                                 | -->
<!-- =================================================================================== -->
<robot name="doozy" xmlns:xacro="http://www.ros.org/wiki/xacro">
  <material name="body_color">
    <color rgba="0.500 0.500 0.500 1.000"/>
  </material>
  <material name="wheel_color">
    <color rgba="0.700 0.700 0.700 1.000"/>
  </material>
  <transmission name="motor_fr_tran">
    <type>transmission_interface/SimpleTransmission</type>
    <joint name="motor_fr">
      <hardwareInterface>hardware_interface/EffortJointInterface</hardwareInterface>
    </joint>
    <actuator name="motor_fr_actr">
      <hardwareInterface>hardware_interface/EffortJointInterface</hardwareInterface>
      <mechanicalReduction>1</mechanicalReduction>
    </actuator>
  </transmission>
  <transmission name="motor_fl_tran">
    <type>transmission_interface/SimpleTransmission</type>
    <joint name="motor_fl">
      <hardwareInterface>hardware_interface/EffortJointInterface</hardwareInterface>
    </joint>
    <actuator name="motor_fl_actr">
      <hardwareInterface>hardware_interface/EffortJointInterface</hardwareInterface>
      <mechanicalReduction>1</mechanicalReduction>
    </actuator>
  </transmission>
  <transmission name="motor_bl_tran">
    <type>transmission_interface/SimpleTransmission</type>
    <joint name="motor_bl">
      <hardwareInterface>hardware_interface/EffortJointInterface</hardwareInterface>
    </joint>
    <actuator name="motor_bl_actr">
      <hardwareInterface>hardware_interface/EffortJointInterface</hardwareInterface>
      <mechanicalReduction>1</mechanicalReduction>
    </actuator>
  </transmission>
  <transmission name="motor_br_tran">
    <type>transmission_interface/SimpleTransmission</type>
    <joint name="motor_br">
      <hardwareInterface>hardware_interface/EffortJointInterface</hardwareInterface>
    </joint>
    <actuator name="motor_br_actr">
      <hardwareInterface>hardware_interface/EffortJointInterface</hardwareInterface>
      <mechanicalReduction>1</mechanicalReduction>
    </actuator>
  </transmission>
  <gazebo reference="base_link">
    <material>Gazebo/Grey</material>
  </gazebo>
  <gazebo reference="wheel_fr_1">
    <material>Gazebo/LightGrey</material>
  </gazebo>
  <gazebo reference="wheel_fl_1">
    <material>Gazebo/LightGrey</material>
  </gazebo>
  <gazebo reference="wheel_bl_1">
    <material>Gazebo/LightGrey</material>
  </gazebo>
  <gazebo reference="wheel_br_1">
    <material>Gazebo/LightGrey</material>
  </gazebo>
  <gazebo reference="base_link">
    <mu1>0</mu1>
    <mu2>0</mu2>
    <selfCollide>true</selfCollide>
    <gravity>true</gravity>
  </gazebo>
  <gazebo reference="wheel_fr_1">
    <mu1>0</mu1>
    <mu2>0</mu2>
    <selfCollide>true</selfCollide>
  </gazebo>
  <gazebo reference="wheel_fl_1">
    <mu1>0</mu1>
    <mu2>0</mu2>
    <selfCollide>true</selfCollide>
  </gazebo>
  <gazebo reference="wheel_bl_1">
    <mu1>0</mu1>
    <mu2>0</mu2>
    <selfCollide>true</selfCollide>
  </gazebo>
  <gazebo reference="wheel_br_1">
    <mu1>0</mu1>
    <mu2>0</mu2>
    <selfCollide>true</selfCollide>
  </gazebo>
  <gazebo>
    <plugin filename="libgazebo_ros_control.so" name="control"/>
  </gazebo>
  <gazebo>
    <plugin filename="libgazebo_ros_planar_move.so" name="mecanum_drive">
      <commandTopic>cmd_vel</commandTopic>
      <odometryTopic>odom</odometryTopic>
      <odometryFrame>odom</odometryFrame>
      <odometryRate>100.0</odometryRate>
      <robotBaseFrame>base_link</robotBaseFrame>
      <publishTF>True</publishTF>
    </plugin>
  </gazebo>
  <link name="base_link">
    <inertial>
      <origin rpy="0 0 0" xyz="-0.000688298297224989 1.5751456391869052e-16 0.10192216934639059"/>
      <mass value="49.42140174360976"/>
      <inertia ixx="3.400808" ixy="0.0" ixz="0.001669" iyy="5.304679" iyz="-0.0" izz="8.500348"/>
    </inertial>
    <visual>
      <origin rpy="0 0 0" xyz="0 0 0"/>
      <geometry>
        <mesh filename="package://doozy_description/meshes/base_link.stl" scale="0.001 0.001 0.001"/>
      </geometry>
      <material name="body_color"/>
    </visual>
    <collision>
      <origin rpy="0 0 0" xyz="0 0 0"/>
      <geometry>
        <mesh filename="package://doozy_description/meshes/base_link.stl" scale="0.001 0.001 0.001"/>
      </geometry>
    </collision>
  </link>
  <link name="wheel_fr">
    <inertial>
      <origin rpy="0 0 0" xyz="-1.6231938637645271e-06 -0.03791410954438729 6.6563337141889445e-06"/>
      <mass value="2.9254253401761314"/>
      <inertia ixx="0.009698" ixy="-0.0" ixz="0.0" iyy="0.016455" iyz="0.0" izz="0.009697"/>
    </inertial>
    <visual>
      <origin rpy="0 0 0" xyz="-0.425 0.426 -0.102"/>
      <geometry>
        <mesh filename="package://doozy_description/meshes/wheel_fr.stl" scale="0.001 0.001 0.001"/>
      </geometry>
      <material name="wheel_color"/>
    </visual>
    <collision>
      <origin rpy="0 0 0" xyz="-0.425 0.426 -0.102"/>
      <geometry>
        <mesh filename="package://doozy_description/meshes/wheel_fr.stl" scale="0.001 0.001 0.001"/>
      </geometry>
    </collision>
  </link>
  <link name="wheel_fl">
    <inertial>
      <origin rpy="0 0 0" xyz="-1.6273189041293712e-06 0.037914108528931734 6.657952042840587e-06"/>
      <mass value="2.9254254631047467"/>
      <inertia ixx="0.009698" ixy="0.0" ixz="0.0" iyy="0.016455" iyz="-0.0" izz="0.009697"/>
    </inertial>
    <visual>
      <origin rpy="0 0 0" xyz="-0.425 -0.426 -0.102"/>
      <geometry>
        <mesh filename="package://doozy_description/meshes/wheel_fl.stl" scale="0.001 0.001 0.001"/>
      </geometry>
      <material name="wheel_color"/>
    </visual>
    <collision>
      <origin rpy="0 0 0" xyz="-0.425 -0.426 -0.102"/>
      <geometry>
        <mesh filename="package://doozy_description/meshes/wheel_fl.stl" scale="0.001 0.001 0.001"/>
      </geometry>
    </collision>
  </link>
  <link name="wheel_bl">
    <inertial>
      <origin rpy="0 0 0" xyz="-1.3662729291818998e-06 0.03788965045500853 6.656333802451675e-06"/>
      <mass value="2.925425340175096"/>
      <inertia ixx="0.009698" ixy="-1e-06" ixz="0.0" iyy="0.016456" iyz="0.0" izz="0.009697"/>
    </inertial>
    <visual>
      <origin rpy="0 0 0" xyz="0.425 -0.426 -0.102"/>
      <geometry>
        <mesh filename="package://doozy_description/meshes/wheel_bl.stl" scale="0.001 0.001 0.001"/>
      </geometry>
      <material name="wheel_color"/>
    </visual>
    <collision>
      <origin rpy="0 0 0" xyz="0.425 -0.426 -0.102"/>
      <geometry>
        <mesh filename="package://doozy_description/meshes/wheel_bl.stl" scale="0.001 0.001 0.001"/>
      </geometry>
    </collision>
  </link>
  <link name="wheel_br">
    <inertial>
      <origin rpy="0 0 0" xyz="-1.3697194627959597e-06 -0.03788965136144423 6.657912586596759e-06"/>
      <mass value="2.925425404496671"/>
      <inertia ixx="0.009698" ixy="1e-06" ixz="0.0" iyy="0.016456" iyz="-0.0" izz="0.009697"/>
    </inertial>
    <visual>
      <origin rpy="0 0 0" xyz="0.425 0.426 -0.102"/>
      <geometry>
        <mesh filename="package://doozy_description/meshes/wheel_br.stl" scale="0.001 0.001 0.001"/>
      </geometry>
      <material name="wheel_color"/>
    </visual>
    <collision>
      <origin rpy="0 0 0" xyz="0.425 0.426 -0.102"/>
      <geometry>
        <mesh filename="package://doozy_description/meshes/wheel_br.stl" scale="0.001 0.001 0.001"/>
      </geometry>
    </collision>
  </link>
  <joint name="motor_fr" type="continuous">
    <origin rpy="0 0 0" xyz="0.425 -0.426 0.102"/>
    <parent link="base_link"/>
    <child link="wheel_fr"/>
    <axis xyz="0.0 0.01 0.0"/>
  </joint>
  <joint name="motor_fl" type="continuous">
    <origin rpy="0 0 0" xyz="0.425 0.426 0.102"/>
    <parent link="base_link"/>
    <child link="wheel_fl"/>
    <axis xyz="0.0 0.01 0.0"/>
  </joint>
  <joint name="motor_bl" type="continuous">
    <origin rpy="0 0 0" xyz="-0.425 0.426 0.102"/>
    <parent link="base_link"/>
    <child link="wheel_bl"/>
    <axis xyz="0.0 0.01 0.0"/>
  </joint>
  <joint name="motor_br" type="continuous">
    <origin rpy="0 0 0" xyz="-0.425 -0.426 0.102"/>
    <parent link="base_link"/>
    <child link="wheel_br"/>
    <axis xyz="0.0 0.01 0.0"/>
  </joint>
</robot>
